Traceback (most recent call last):
  File "/Users/doya/miniforge3/lib/python3.9/site-packages/jupyter_cache/executors/utils.py", line 51, in single_nb_execution
    executenb(
  File "/Users/doya/miniforge3/lib/python3.9/site-packages/nbclient/client.py", line 1204, in execute
    return NotebookClient(nb=nb, resources=resources, km=km, **kwargs).execute()
  File "/Users/doya/miniforge3/lib/python3.9/site-packages/nbclient/util.py", line 84, in wrapped
    return just_run(coro(*args, **kwargs))
  File "/Users/doya/miniforge3/lib/python3.9/site-packages/nbclient/util.py", line 62, in just_run
    return loop.run_until_complete(coro)
  File "/Users/doya/miniforge3/lib/python3.9/asyncio/base_events.py", line 647, in run_until_complete
    return future.result()
  File "/Users/doya/miniforge3/lib/python3.9/site-packages/nbclient/client.py", line 663, in async_execute
    await self.async_execute_cell(
  File "/Users/doya/miniforge3/lib/python3.9/site-packages/nbclient/client.py", line 965, in async_execute_cell
    await self._check_raise_for_error(cell, cell_index, exec_reply)
  File "/Users/doya/miniforge3/lib/python3.9/site-packages/nbclient/client.py", line 862, in _check_raise_for_error
    raise CellExecutionError.from_cell_and_msg(cell, exec_reply_content)
nbclient.exceptions.CellExecutionError: An error occurred while executing the following cell:
------------------
%run haisai.py
------------------

[0;31m---------------------------------------------------------------------------[0m
[0;31mOSError[0m                                   Traceback (most recent call last)
File [0;32m~/miniforge3/lib/python3.9/site-packages/IPython/core/magics/execution.py:701[0m, in [0;36mExecutionMagics.run[0;34m(self, parameter_s, runner, file_finder)[0m
[1;32m    700[0m     fpath [38;5;241m=[39m arg_lst[[38;5;241m0[39m]
[0;32m--> 701[0m     filename [38;5;241m=[39m [43mfile_finder[49m[43m([49m[43mfpath[49m[43m)[49m
[1;32m    702[0m [38;5;28;01mexcept[39;00m [38;5;167;01mIndexError[39;00m [38;5;28;01mas[39;00m e:

File [0;32m~/miniforge3/lib/python3.9/site-packages/IPython/utils/path.py:90[0m, in [0;36mget_py_filename[0;34m(name)[0m
[1;32m     89[0m         [38;5;28;01mreturn[39;00m py_name
[0;32m---> 90[0m [38;5;28;01mraise[39;00m [38;5;167;01mIOError[39;00m([38;5;124m"[39m[38;5;124mFile `[39m[38;5;132;01m%r[39;00m[38;5;124m` not found.[39m[38;5;124m"[39m [38;5;241m%[39m name)

[0;31mOSError[0m: File `'haisai.py'` not found.

The above exception was the direct cause of the following exception:

[0;31mException[0m                                 Traceback (most recent call last)
Cell [0;32mIn[19], line 1[0m
[0;32m----> 1[0m [43mget_ipython[49m[43m([49m[43m)[49m[38;5;241;43m.[39;49m[43mrun_line_magic[49m[43m([49m[38;5;124;43m'[39;49m[38;5;124;43mrun[39;49m[38;5;124;43m'[39;49m[43m,[49m[43m [49m[38;5;124;43m'[39;49m[38;5;124;43mhaisai.py[39;49m[38;5;124;43m'[39;49m[43m)[49m

File [0;32m~/miniforge3/lib/python3.9/site-packages/IPython/core/interactiveshell.py:2417[0m, in [0;36mInteractiveShell.run_line_magic[0;34m(self, magic_name, line, _stack_depth)[0m
[1;32m   2415[0m     kwargs[[38;5;124m'[39m[38;5;124mlocal_ns[39m[38;5;124m'[39m] [38;5;241m=[39m [38;5;28mself[39m[38;5;241m.[39mget_local_scope(stack_depth)
[1;32m   2416[0m [38;5;28;01mwith[39;00m [38;5;28mself[39m[38;5;241m.[39mbuiltin_trap:
[0;32m-> 2417[0m     result [38;5;241m=[39m [43mfn[49m[43m([49m[38;5;241;43m*[39;49m[43margs[49m[43m,[49m[43m [49m[38;5;241;43m*[39;49m[38;5;241;43m*[39;49m[43mkwargs[49m[43m)[49m
[1;32m   2419[0m [38;5;66;03m# The code below prevents the output from being displayed[39;00m
[1;32m   2420[0m [38;5;66;03m# when using magics with decodator @output_can_be_silenced[39;00m
[1;32m   2421[0m [38;5;66;03m# when the last Python token in the expression is a ';'.[39;00m
[1;32m   2422[0m [38;5;28;01mif[39;00m [38;5;28mgetattr[39m(fn, magic[38;5;241m.[39mMAGIC_OUTPUT_CAN_BE_SILENCED, [38;5;28;01mFalse[39;00m):

File [0;32m~/miniforge3/lib/python3.9/site-packages/IPython/core/magics/execution.py:712[0m, in [0;36mExecutionMagics.run[0;34m(self, parameter_s, runner, file_finder)[0m
[1;32m    710[0m     [38;5;28;01mif[39;00m os[38;5;241m.[39mname [38;5;241m==[39m [38;5;124m'[39m[38;5;124mnt[39m[38;5;124m'[39m [38;5;129;01mand[39;00m re[38;5;241m.[39mmatch([38;5;124mr[39m[38;5;124m"[39m[38;5;124m^[39m[38;5;124m'[39m[38;5;124m.*[39m[38;5;124m'[39m[38;5;124m$[39m[38;5;124m"[39m,fpath):
[1;32m    711[0m         warn([38;5;124m'[39m[38;5;124mFor Windows, use double quotes to wrap a filename: [39m[38;5;132;01m%r[39;00m[38;5;124mun [39m[38;5;124m"[39m[38;5;124mmypath[39m[38;5;130;01m\\[39;00m[38;5;124mmyfile.py[39m[38;5;124m"[39m[38;5;124m'[39m)
[0;32m--> 712[0m     [38;5;28;01mraise[39;00m [38;5;167;01mException[39;00m(msg) [38;5;28;01mfrom[39;00m [38;5;21;01me[39;00m
[1;32m    713[0m [38;5;28;01mexcept[39;00m [38;5;167;01mTypeError[39;00m:
[1;32m    714[0m     [38;5;28;01mif[39;00m fpath [38;5;129;01min[39;00m sys[38;5;241m.[39mmeta_path:

[0;31mException[0m: File `'haisai.py'` not found.
Exception: File `'haisai.py'` not found.

