Traceback (most recent call last):
  File "/opt/anaconda3/lib/python3.11/site-packages/jupyter_cache/executors/utils.py", line 58, in single_nb_execution
    executenb(
  File "/opt/anaconda3/lib/python3.11/site-packages/nbclient/client.py", line 1305, in execute
    return NotebookClient(nb=nb, resources=resources, km=km, **kwargs).execute()
           ^^^^^^^^^^^^^^^^^^^^^^^^^^^^^^^^^^^^^^^^^^^^^^^^^^^^^^^^^^^^^^^^^^^^^
  File "/opt/anaconda3/lib/python3.11/site-packages/jupyter_core/utils/__init__.py", line 173, in wrapped
    return loop.run_until_complete(inner)
           ^^^^^^^^^^^^^^^^^^^^^^^^^^^^^^
  File "/opt/anaconda3/lib/python3.11/asyncio/base_events.py", line 650, in run_until_complete
    return future.result()
           ^^^^^^^^^^^^^^^
  File "/opt/anaconda3/lib/python3.11/contextlib.py", line 222, in __aexit__
    await self.gen.athrow(typ, value, traceback)
  File "/opt/anaconda3/lib/python3.11/site-packages/nbclient/client.py", line 650, in async_setup_kernel
    yield
  File "/opt/anaconda3/lib/python3.11/site-packages/nbclient/client.py", line 705, in async_execute
    await self.async_execute_cell(
  File "/opt/anaconda3/lib/python3.11/site-packages/nbclient/client.py", line 1058, in async_execute_cell
    await self._check_raise_for_error(cell, cell_index, exec_reply)
  File "/opt/anaconda3/lib/python3.11/site-packages/nbclient/client.py", line 914, in _check_raise_for_error
    raise CellExecutionError.from_cell_and_msg(cell, exec_reply_content)
nbclient.exceptions.CellExecutionError: An error occurred while executing the following cell:
------------------
print(F'weight {a} g\n{'volume':10}{b:6d} cc\n{'density':10}{a/b:6.3f} g/cc')
------------------


[0;36m  Cell [0;32mIn[19], line 1[0;36m[0m
[0;31m    print(F'weight {a} g\n{'volume':10}{b:6d} cc\n{'density':10}{a/b:6.3f} g/cc')[0m
[0m                            ^[0m
[0;31mSyntaxError[0m[0;31m:[0m f-string: expecting '}'


