Traceback (most recent call last):
  File "/Users/doya/miniforge3/lib/python3.9/site-packages/jupyter_cache/executors/utils.py", line 51, in single_nb_execution
    executenb(
  File "/Users/doya/miniforge3/lib/python3.9/site-packages/nbclient/client.py", line 1204, in execute
    return NotebookClient(nb=nb, resources=resources, km=km, **kwargs).execute()
  File "/Users/doya/miniforge3/lib/python3.9/site-packages/nbclient/util.py", line 84, in wrapped
    return just_run(coro(*args, **kwargs))
  File "/Users/doya/miniforge3/lib/python3.9/site-packages/nbclient/util.py", line 62, in just_run
    return loop.run_until_complete(coro)
  File "/Users/doya/miniforge3/lib/python3.9/asyncio/base_events.py", line 647, in run_until_complete
    return future.result()
  File "/Users/doya/miniforge3/lib/python3.9/site-packages/nbclient/client.py", line 663, in async_execute
    await self.async_execute_cell(
  File "/Users/doya/miniforge3/lib/python3.9/site-packages/nbclient/client.py", line 965, in async_execute_cell
    await self._check_raise_for_error(cell, cell_index, exec_reply)
  File "/Users/doya/miniforge3/lib/python3.9/site-packages/nbclient/client.py", line 862, in _check_raise_for_error
    raise CellExecutionError.from_cell_and_msg(cell, exec_reply_content)
nbclient.exceptions.CellExecutionError: An error occurred while executing the following cell:
------------------
def f(x, a, b, deriv=True):
    """y[0] = a[0] + a[1]*x[0]**2 + a[2]*x[1]**2\\
    y[1] = b[0] + b[1]*x[0] + b[2]*x[1]
    also return the Jacobian if derive==True"""
    y0 = 
    y1 = 
    if deriv:
        J = 
        
        return np.array([y0, y1]), np.array(J)
    else:
        return np.array([y0, y1])
------------------

[0;36m  Cell [0;32mIn[2], line 5[0;36m[0m
[0;31m    y0 =[0m
[0m         ^[0m
[0;31mSyntaxError[0m[0;31m:[0m invalid syntax

SyntaxError: invalid syntax (3608421478.py, line 5)

