Traceback (most recent call last):
  File "/opt/anaconda3/lib/python3.11/site-packages/jupyter_cache/executors/utils.py", line 58, in single_nb_execution
    executenb(
  File "/opt/anaconda3/lib/python3.11/site-packages/nbclient/client.py", line 1305, in execute
    return NotebookClient(nb=nb, resources=resources, km=km, **kwargs).execute()
           ^^^^^^^^^^^^^^^^^^^^^^^^^^^^^^^^^^^^^^^^^^^^^^^^^^^^^^^^^^^^^^^^^^^^^
  File "/opt/anaconda3/lib/python3.11/site-packages/jupyter_core/utils/__init__.py", line 173, in wrapped
    return loop.run_until_complete(inner)
           ^^^^^^^^^^^^^^^^^^^^^^^^^^^^^^
  File "/opt/anaconda3/lib/python3.11/asyncio/base_events.py", line 650, in run_until_complete
    return future.result()
           ^^^^^^^^^^^^^^^
  File "/opt/anaconda3/lib/python3.11/contextlib.py", line 222, in __aexit__
    await self.gen.athrow(typ, value, traceback)
  File "/opt/anaconda3/lib/python3.11/site-packages/nbclient/client.py", line 650, in async_setup_kernel
    yield
  File "/opt/anaconda3/lib/python3.11/site-packages/nbclient/client.py", line 705, in async_execute
    await self.async_execute_cell(
  File "/opt/anaconda3/lib/python3.11/site-packages/nbclient/client.py", line 1058, in async_execute_cell
    await self._check_raise_for_error(cell, cell_index, exec_reply)
  File "/opt/anaconda3/lib/python3.11/site-packages/nbclient/client.py", line 914, in _check_raise_for_error
    raise CellExecutionError.from_cell_and_msg(cell, exec_reply_content)
nbclient.exceptions.CellExecutionError: An error occurred while executing the following cell:
------------------
y0 = np.array([0, 0])
t = np.arange(0, 100, 0.1)
y = odeint(fhn, y0, t, args=(0.5,))
plt.plot(t, y, '.-')  # trajectory
------------------


[0;31m---------------------------------------------------------------------------[0m
[0;31mRuntimeError[0m                              Traceback (most recent call last)
Cell [0;32mIn[7], line 3[0m
[1;32m      1[0m y0 [38;5;241m=[39m np[38;5;241m.[39marray([[38;5;241m0[39m, [38;5;241m0[39m])
[1;32m      2[0m t [38;5;241m=[39m np[38;5;241m.[39marange([38;5;241m0[39m, [38;5;241m100[39m, [38;5;241m0.1[39m)
[0;32m----> 3[0m y [38;5;241m=[39m odeint(fhn, y0, t, args[38;5;241m=[39m([38;5;241m0.5[39m,))
[1;32m      4[0m plt[38;5;241m.[39mplot(t, y, [38;5;124m'[39m[38;5;124m.-[39m[38;5;124m'[39m)

File [0;32m/opt/anaconda3/lib/python3.11/site-packages/scipy/integrate/_odepack_py.py:242[0m, in [0;36modeint[0;34m(func, y0, t, args, Dfun, col_deriv, full_output, ml, mu, rtol, atol, tcrit, h0, hmax, hmin, ixpr, mxstep, mxhnil, mxordn, mxords, printmessg, tfirst)[0m
[1;32m    240[0m t [38;5;241m=[39m copy(t)
[1;32m    241[0m y0 [38;5;241m=[39m copy(y0)
[0;32m--> 242[0m output [38;5;241m=[39m _odepack[38;5;241m.[39modeint(func, y0, t, args, Dfun, col_deriv, ml, mu,
[1;32m    243[0m                          full_output, rtol, atol, tcrit, h0, hmax, hmin,
[1;32m    244[0m                          ixpr, mxstep, mxhnil, mxordn, mxords,
[1;32m    245[0m                          [38;5;28mint[39m([38;5;28mbool[39m(tfirst)))
[1;32m    246[0m [38;5;28;01mif[39;00m output[[38;5;241m-[39m[38;5;241m1[39m] [38;5;241m<[39m [38;5;241m0[39m:
[1;32m    247[0m     warning_msg [38;5;241m=[39m _msgs[output[[38;5;241m-[39m[38;5;241m1[39m]] [38;5;241m+[39m [38;5;124m"[39m[38;5;124m Run with full_output = 1 to get quantitative information.[39m[38;5;124m"[39m

[0;31mRuntimeError[0m: The size of the array returned by func (1) does not match the size of y0 (2).

